Workbook

Sheet Start Here
B2: The Biomolecular Design Curriculum
B3: Progress tracker · third edition · compiled October 2026
B5: What this is | C5: A multi-year self-study program in every computational method for proteins, DNA and RNA, the AI research upstream of it, and the engineering that makes it fast.
B6: Videos tracked | C6: 3,271 unique talks and lectures
B7: Timed runtime | C7: about 2,945 hours (not every entry carries a duration)
B8: Papers paired | C8: 547 citations, linked to the section that discusses them
B9: Watch-then-read pairs | C9: 467 — the core study device of this curriculum
B10: Derivation checkpoints | C10: 73 — these are what convert watching into ability
B11: Capstone projects | C11: 11
B13: HOW TO USE THIS
B14: 1 · Progress Tracker | C14: The main sheet. Every video in reading order. Set Status to Watching or Done and the Dashboard updates itself. Filter by Part, Section or Priority to carve out a study block.
B15: · the paper columns | C15: Paired paper is the citation to read alongside the talk; Paper is a link straight to it (arXiv or DOI where the citation carries one, otherwise a Scholar search). How paired says where the pairing came from: stated with the talk is the strongest, paired reading comes from the curriculum's own watch-then-read tables, and section reading means it is the reading for that section rather than for that one talk.
B16: 2 · Core Path | C16: If you do nothing else, do this. Roughly 150 hours that take you from running tools to understanding them.
B17: 3 · Dashboard | C17: Live completion by Part and by Section. Formula-driven; do not type into it.
B18: 4 · Paired Reading | C18: Watch this, then read that, holding this question. The single most useful device here — the gap between a talk and its paper is where the real understanding sits.
B19: 5 · Checkpoints | C19: 73 things to derive from a blank page. Only the third state — 'can reproduce from blank paper' — counts.
B20: 6 · Capstones | C20: 11 projects, each cross-referenced from the family that motivates it.
B21: 7 · Papers | C21: Every citation, by section.
B22: 8 · Sections | C22: The full table of contents with counts and hours.
B24: A note on the hours | C24: The runtime figure is not a target. It is the size of the field's recorded output. Nobody should watch all of it and this is not built on the assumption that anyone will. Treat it as a reference you work through and keep returning to.
B25: Priority column | C25: ★ marks entries the curriculum flags as the ones to watch first within their section.
B26: Dead links | C26: Checked October 2026: none dead. A small number have embedding disabled, which means they play on YouTube but cannot be iframed.

Sheet Progress Tracker
A1: # | B1: Part | C1: Section | D1: Title | E1: Speaker / host | F1: Duration | G1: Hours | H1: Priority | I1: Status | J1: Date done | K1: Notes | L1: Watch | M1: Paired paper | N1: Paper | O1: How paired | P1: Also appears in
A2: 1 | B2: Part I - Foundations | C2: MIT 18.065 - Matrix Methods in Data Analysis, Signal Processing and Machine Learning | D2: Course Introduction | F2: 7:04 | G2: 0.12 | I2: Not started | L2: ▶ watch | O2: course lecture - no single paper
A3: 2 | B3: Part I - Foundations | C3: MIT 18.065 - Matrix Methods in Data Analysis, Signal Processing and Machine Learning | D3: Interview with Gilbert Strang on Teaching Matrix Methods | F3: 8:07 | G3: 0.14 | I3: Not started | L3: ▶ watch | O3: course lecture - no single paper
A4: 3 | B4: Part I - Foundations | C4: MIT 18.065 - Matrix Methods in Data Analysis, Signal Processing and Machine Learning | D4: The Column Space of A Contains All Vectors Ax | F4: 52:15 | G4: 0.87 | I4: Not started | L4: ▶ watch | O4: course lecture - no single paper
A5: 4 | B5: Part I - Foundations | C5: MIT 18.065 - Matrix Methods in Data Analysis, Signal Processing and Machine Learning | D5: Multiplying and Factoring Matrices | F5: 48:26 | G5: 0.81 | I5: Not started | L5: ▶ watch | O5: course lecture - no single paper
A6: 5 | B6: Part I - Foundations | C6: MIT 18.065 - Matrix Methods in Data Analysis, Signal Processing and Machine Learning | D6: Orthonormal Columns in Q Give Q'Q = I | F6: 49:24 | G6: 0.82 | I6: Not started | L6: ▶ watch | O6: course lecture - no single paper
A7: 6 | B7: Part I - Foundations | C7: MIT 18.065 - Matrix Methods in Data Analysis, Signal Processing and Machine Learning | D7: Eigenvalues and Eigenvectors | F7: 48:56 | G7: 0.82 | I7: Not started | L7: ▶ watch | O7: course lecture - no single paper
A8: 7 | B8: Part I - Foundations | C8: MIT 18.065 - Matrix Methods in Data Analysis, Signal Processing and Machine Learning | D8: Positive Definite and Semidefinite Matrices | F8: 45:27 | G8: 0.76 | I8: Not started | L8: ▶ watch | O8: course lecture - no single paper
A9: 8 | B9: Part I - Foundations | C9: MIT 18.065 - Matrix Methods in Data Analysis, Signal Processing and Machine Learning | D9: Singular Value Decomposition (SVD | F9: 53:34 | G9: 0.89 | I9: Not started | L9: ▶ watch | O9: course lecture - no single paper
A10: 9 | B10: Part I - Foundations | C10: MIT 18.065 - Matrix Methods in Data Analysis, Signal Processing and Machine Learning | D10: Eckart-Young: The Closest Rank k Matrix to A | F10: 47:16 | G10: 0.79 | H10: ★ | I10: Not started | L10: ▶ watch | O10: course lecture - no single paper
A11: 10 | B11: Part I - Foundations | C11: MIT 18.065 - Matrix Methods in Data Analysis, Signal Processing and Machine Learning | D11: Norms of Vectors and Matrices | F11: 49:21 | G11: 0.82 | I11: Not started | L11: ▶ watch | O11: course lecture - no single paper
A12: 11 | B12: Part I - Foundations | C12: MIT 18.065 - Matrix Methods in Data Analysis, Signal Processing and Machine Learning | D12: Four Ways to Solve Least Squares Problems | F12: 49:51 | G12: 0.83 | I12: Not started | L12: ▶ watch | O12: course lecture - no single paper
A13: 12 | B13: Part I - Foundations | C13: MIT 18.065 - Matrix Methods in Data Analysis, Signal Processing and Machine Learning | D13: Survey of Difficulties with Ax = b | F13: 49:36 | G13: 0.83 | I13: Not started | L13: ▶ watch | O13: course lecture - no single paper
A14: 13 | B14: Part I - Foundations | C14: MIT 18.065 - Matrix Methods in Data Analysis, Signal Processing and Machine Learning | D14: Minimizing ‖x‖ Subject to Ax = b | F14: 50:22 | G14: 0.84 | I14: Not started | L14: ▶ watch | O14: course lecture - no single paper
A15: 14 | B15: Part I - Foundations | C15: MIT 18.065 - Matrix Methods in Data Analysis, Signal Processing and Machine Learning | D15: Computing Eigenvalues and Singular Values | F15: 49:28 | G15: 0.82 | I15: Not started | L15: ▶ watch | O15: course lecture - no single paper
A16: 15 | B16: Part I - Foundations | C16: MIT 18.065 - Matrix Methods in Data Analysis, Signal Processing and Machine Learning | D16: Randomized Matrix Multiplication | F16: 52:24 | G16: 0.87 | H16: ★ | I16: Not started | L16: ▶ watch | O16: course lecture - no single paper
A17: 16 | B17: Part I - Foundations | C17: MIT 18.065 - Matrix Methods in Data Analysis, Signal Processing and Machine Learning | D17: Low Rank Changes in A and Its Inverse | F17: 50:34 | G17: 0.84 | I17: Not started | L17: ▶ watch | O17: course lecture - no single paper
A18: 17 | B18: Part I - Foundations | C18: MIT 18.065 - Matrix Methods in Data Analysis, Signal Processing and Machine Learning | D18: Matrices A(t) Depending on t, Derivative = dA/dt | F18: 50:52 | G18: 0.85 | I18: Not started | L18: ▶ watch | O18: course lecture - no single paper
A19: 18 | B19: Part I - Foundations | C19: MIT 18.065 - Matrix Methods in Data Analysis, Signal Processing and Machine Learning | D19: Derivatives of Inverse and Singular Values | F19: 43:08 | G19: 0.72 | I19: Not started | L19: ▶ watch | O19: course lecture - no single paper
A20: 19 | B20: Part I - Foundations | C20: MIT 18.065 - Matrix Methods in Data Analysis, Signal Processing and Machine Learning | D20: Rapidly Decreasing Singular Values | F20: 50:34 | G20: 0.84 | H20: ★ | I20: Not started | L20: ▶ watch | O20: course lecture - no single paper
A21: 20 | B21: Part I - Foundations | C21: MIT 18.065 - Matrix Methods in Data Analysis, Signal Processing and Machine Learning | D21: Counting Parameters in SVD, LU, QR, Saddle Points | F21: 49:00 | G21: 0.82 | I21: Not started | L21: ▶ watch | O21: course lecture - no single paper
A22: 21 | B22: Part I - Foundations | C22: MIT 18.065 - Matrix Methods in Data Analysis, Signal Processing and Machine Learning | D22: Saddle Points Continued, Maxmin Principle | F22: 52:13 | G22: 0.87 | I22: Not started | L22: ▶ watch | O22: course lecture - no single paper
A23: 22 | B23: Part I - Foundations | C23: MIT 18.065 - Matrix Methods in Data Analysis, Signal Processing and Machine Learning | D23: Definitions and Inequalities | F23: 55:01 | G23: 0.92 | I23: Not started | L23: ▶ watch | O23: course lecture - no single paper
A24: 23 | B24: Part I - Foundations | C24: MIT 18.065 - Matrix Methods in Data Analysis, Signal Processing and Machine Learning | D24: Minimizing a Function Step by Step | F24: 53:45 | G24: 0.9 | I24: Not started | L24: ▶ watch | O24: course lecture - no single paper
A25: 24 | B25: Part I - Foundations | C25: MIT 18.065 - Matrix Methods in Data Analysis, Signal Processing and Machine Learning | D25: Gradient Descent: Downhill to a Minimum | F25: 52:44 | G25: 0.88 | I25: Not started | L25: ▶ watch | O25: course lecture - no single paper
A26: 25 | B26: Part I - Foundations | C26: MIT 18.065 - Matrix Methods in Data Analysis, Signal Processing and Machine Learning | D26: Accelerating Gradient Descent (Use Momentum | F26: 49:02 | G26: 0.82 | I26: Not started | L26: ▶ watch | O26: course lecture - no single paper
A27: 26 | B27: Part I - Foundations | C27: MIT 18.065 - Matrix Methods in Data Analysis, Signal Processing and Machine Learning | D27: Linear Programming and Two-Person Games | F27: 53:34 | G27: 0.89 | I27: Not started | L27: ▶ watch | O27: course lecture - no single paper
A28: 27 | B28: Part I - Foundations | C28: MIT 18.065 - Matrix Methods in Data Analysis, Signal Processing and Machine Learning | D28: Stochastic Gradient Descent | F28: 53:03 | G28: 0.88 | I28: Not started | L28: ▶ watch | O28: course lecture - no single paper
A29: 28 | B29: Part I - Foundations | C29: MIT 18.065 - Matrix Methods in Data Analysis, Signal Processing and Machine Learning | D29: Structure of Neural Nets for Deep Learning | F29: 53:17 | G29: 0.89 | I29: Not started | L29: ▶ watch | O29: course lecture - no single paper
A30: 29 | B30: Part I - Foundations | C30: MIT 18.065 - Matrix Methods in Data Analysis, Signal Processing and Machine Learning | D30: Backpropagation: Find Partial Derivatives | F30: 52:38 | G30: 0.88 | I30: Not started | L30: ▶ watch | O30: course lecture - no single paper
A31: 30 | B31: Part I - Foundations | C31: MIT 18.065 - Matrix Methods in Data Analysis, Signal Processing and Machine Learning | D31: Completing a Rank-One Matrix, Circulants | F31: 49:53 | G31: 0.83 | I31: Not started | L31: ▶ watch | O31: course lecture - no single paper
A32: 31 | B32: Part I - Foundations | C32: MIT 18.065 - Matrix Methods in Data Analysis, Signal Processing and Machine Learning | D32: Eigenvectors of Circulant Matrices: Fourier Matrix | F32: 52:37 | G32: 0.88 | I32: Not started | L32: ▶ watch | O32: course lecture - no single paper
... A44: 43 | B44: Part I - Foundations | C44: MIT 18.S096 - Matrix Calculus for Machine Learning and Beyond | D44: Gradients and Inner Products in Other Vector Spaces | F44: 1:03:49 | G44: 1.06 | I44: Not started | L44: ▶ watch | O44: course lecture - no single paper
A45: 44 | B45: Part I - Foundations | C45: MIT 18.S096 - Matrix Calculus for Machine Learning and Beyond | D45: Nonlinear Root Finding, Optimization, and Adjoint Gradient Methods | F45: 44:26 | G45: 0.74 | H45: ★ | I45: Not started | L45: ▶ watch | O45: course lecture - no single paper
A46: 45 | B46: Part I - Foundations | C46: MIT 18.S096 - Matrix Calculus for Machine Learning and Beyond | D46: Derivative of Matrix Determinant and Inverse | F46: 28:03 | G46: 0.47 | I46: Not started | L46: ▶ watch | O46: course lecture - no single paper
A47: 46 | B47: Part I - Foundations | C47: MIT 18.S096 - Matrix Calculus for Machine Learning and Beyond | D47: Forward Automatic Differentiation via Dual Numbers | F47: 36:02 | G47: 0.6 | I47: Not started | L47: ▶ watch | O47: course lecture - no single paper
A48: 47 | B48: Part I - Foundations | C48: MIT 18.S096 - Matrix Calculus for Machine Learning and Beyond | D48: Differentiation on Computational Graphs | F48: 32:46 | G48: 0.55 | I48: Not started | L48: ▶ watch | O48: course lecture - no single paper
A49: 48 | B49: Part I - Foundations | C49: MIT 18.S096 - Matrix Calculus for Machine Learning and Beyond | D49: Adjoint Differentiation of ODE Solutions | F49: 58:21 | G49: 0.97 | H49: ★ | I49: Not started | L49: ▶ watch | O49: course lecture - no single paper
A50: 49 | B50: Part I - Foundations | C50: MIT 18.S096 - Matrix Calculus for Machine Learning and Beyond | D50: Calculus of Variations and Gradients of Functionals | F50: 42:32 | G50: 0.71 | I50: Not started | L50: ▶ watch | O50: course lecture - no single paper
A51: 50 | B51: Part I - Foundations | C51: MIT 18.S096 - Matrix Calculus for Machine Learning and Beyond | D51: Derivatives of Random Functions | F51: 1:06:18 | G51: 1.1 | I51: Not started | L51: ▶ watch | O51: course lecture - no single paper
...

Sheet Dashboard
B2: Progress
B3: Driven by the Status column on Progress Tracker. Nothing here needs editing.
B5: OVERALL
B6: Videos total | C6: =COUNTA('Progress Tracker'!A2:A3272)
B7: Done | C7: =COUNTIF('Progress Tracker'!$I$2:$I$3272,"Done")
B8: Watching | C8: =COUNTIF('Progress Tracker'!$I$2:$I$3272,"Watching")
B9: Skipped | C9: =COUNTIF('Progress Tracker'!$I$2:$I$3272,"Skipped")
B10: Percent done | C10: =IFERROR(COUNTIF('Progress Tracker'!$I$2:$I$3272,"Done")/COUNTA('Progress Tracker'!A2:A3272),0)
B11: Hours total | C11: =ROUND(SUM('Progress Tracker'!$G$2:$G$3272),0)
B12: Hours done | C12: =ROUND(SUMIF('Progress Tracker'!$I$2:$I$3272,"Done",'Progress Tracker'!$G$2:$G$3272),1)
B15: BY PART
B16: Part | C16: Videos | D16: Done | E16: % done | F16: Hours | G16: Hrs done
B17: Part I - Foundations | C17: =COUNTIF('Progress Tracker'!$B$2:$B$3272,$B17) | D17: =COUNTIFS('Progress Tracker'!$B$2:$B$3272,$B17,'Progress Tracker'!$I$2:$I$3272,"Done") | E17: =IFERROR(D17/C17,0) | F17: =ROUND(SUMIF('Progress Tracker'!$B$2:$B$3272,$B17,'Progress Tracker'!$G$2:$G$3272),0) | G17: =ROUND(SUMIFS('Progress Tracker'!$G$2:$G$3272,'Progress Tracker'!$B$2:$B$3272,$B17,'Progress Tracker'!$I$2:$I$3272,"Done"),1)
B18: Part II - The Method Atlas | C18: =COUNTIF('Progress Tracker'!$B$2:$B$3272,$B18) | D18: =COUNTIFS('Progress Tracker'!$B$2:$B$3272,$B18,'Progress Tracker'!$I$2:$I$3272,"Done") | E18: =IFERROR(D18/C18,0) | F18: =ROUND(SUMIF('Progress Tracker'!$B$2:$B$3272,$B18,'Progress Tracker'!$G$2:$G$3272),0) | G18: =ROUND(SUMIFS('Progress Tracker'!$G$2:$G$3272,'Progress Tracker'!$B$2:$B$3272,$B18,'Progress Tracker'!$I$2:$I$3272,"Done"),1)
B19: Part III - Upstream AI Research | C19: =COUNTIF('Progress Tracker'!$B$2:$B$3272,$B19) | D19: =COUNTIFS('Progress Tracker'!$B$2:$B$3272,$B19,'Progress Tracker'!$I$2:$I$3272,"Done") | E19: =IFERROR(D19/C19,0) | F19: =ROUND(SUMIF('Progress Tracker'!$B$2:$B$3272,$B19,'Progress Tracker'!$G$2:$G$3272),0) | G19: =ROUND(SUMIFS('Progress Tracker'!$G$2:$G$3272,'Progress Tracker'!$B$2:$B$3272,$B19,'Progress Tracker'!$I$2:$I$3272,"Done"),1)
B20: Part IV - Performance Engineering | C20: =COUNTIF('Progress Tracker'!$B$2:$B$3272,$B20) | D20: =COUNTIFS('Progress Tracker'!$B$2:$B$3272,$B20,'Progress Tracker'!$I$2:$I$3272,"Done") | E20: =IFERROR(D20/C20,0) | F20: =ROUND(SUMIF('Progress Tracker'!$B$2:$B$3272,$B20,'Progress Tracker'!$G$2:$G$3272),0) | G20: =ROUND(SUMIFS('Progress Tracker'!$G$2:$G$3272,'Progress Tracker'!$B$2:$B$3272,$B20,'Progress Tracker'!$I$2:$I$3272,"Done"),1)
B21: Part V (continued) - Research Craft | C21: =COUNTIF('Progress Tracker'!$B$2:$B$3272,$B21) | D21: =COUNTIFS('Progress Tracker'!$B$2:$B$3272,$B21,'Progress Tracker'!$I$2:$I$3272,"Done") | E21: =IFERROR(D21/C21,0) | F21: =ROUND(SUMIF('Progress Tracker'!$B$2:$B$3272,$B21,'Progress Tracker'!$G$2:$G$3272),0) | G21: =ROUND(SUMIFS('Progress Tracker'!$G$2:$G$3272,'Progress Tracker'!$B$2:$B$3272,$B21,'Progress Tracker'!$I$2:$I$3272,"Done"),1)
B22: Part VI - Appendices | C22: =COUNTIF('Progress Tracker'!$B$2:$B$3272,$B22) | D22: =COUNTIFS('Progress Tracker'!$B$2:$B$3272,$B22,'Progress Tracker'!$I$2:$I$3272,"Done") | E22: =IFERROR(D22/C22,0) | F22: =ROUND(SUMIF('Progress Tracker'!$B$2:$B$3272,$B22,'Progress Tracker'!$G$2:$G$3272),0) | G22: =ROUND(SUMIFS('Progress Tracker'!$G$2:$G$3272,'Progress Tracker'!$B$2:$B$3272,$B22,'Progress Tracker'!$I$2:$I$3272,"Done"),1)
B25: BY SECTION
B26: Section | C26: Videos | D26: Done | E26: % done | F26: Hours
B27: MIT 18.065 - Matrix Methods in Data Analysis, Signal Processing and Machine Learning | C27: =COUNTIF('Progress Tracker'!$C$2:$C$3272,$B27) | D27: =COUNTIFS('Progress Tracker'!$C$2:$C$3272,$B27,'Progress Tracker'!$I$2:$I$3272,"Done") | E27: =IFERROR(D27/C27,0) | F27: =ROUND(SUMIF('Progress Tracker'!$C$2:$C$3272,$B27,'Progress Tracker'!$G$2:$G$3272),1)
B28: MIT 18.S096 - Matrix Calculus for Machine Learning and Beyond | C28: =COUNTIF('Progress Tracker'!$C$2:$C$3272,$B28) | D28: =COUNTIFS('Progress Tracker'!$C$2:$C$3272,$B28,'Progress Tracker'!$I$2:$I$3272,"Done") | E28: =IFERROR(D28/C28,0) | F28: =ROUND(SUMIF('Progress Tracker'!$C$2:$C$3272,$B28,'Progress Tracker'!$G$2:$G$3272),1)
B29: David MacKay - Information Theory, Pattern Recognition and Neural Networks | C29: =COUNTIF('Progress Tracker'!$C$2:$C$3272,$B29) | D29: =COUNTIFS('Progress Tracker'!$C$2:$C$3272,$B29,'Progress Tracker'!$I$2:$I$3272,"Done") | E29: =IFERROR(D29/C29,0) | F29: =ROUND(SUMIF('Progress Tracker'!$C$2:$C$3272,$B29,'Progress Tracker'!$G$2:$G$3272),1)
B30: Unit I - Thermodynamics | C30: =COUNTIF('Progress Tracker'!$C$2:$C$3272,$B30) | D30: =COUNTIFS('Progress Tracker'!$C$2:$C$3272,$B30,'Progress Tracker'!$I$2:$I$3272,"Done") | E30: =IFERROR(D30/C30,0) | F30: =ROUND(SUMIF('Progress Tracker'!$C$2:$C$3272,$B30,'Progress Tracker'!$G$2:$G$3272),1)
B31: Unit II - Probability | C31: =COUNTIF('Progress Tracker'!$C$2:$C$3272,$B31) | D31: =COUNTIFS('Progress Tracker'!$C$2:$C$3272,$B31,'Progress Tracker'!$I$2:$I$3272,"Done") | E31: =IFERROR(D31/C31,0) | F31: =ROUND(SUMIF('Progress Tracker'!$C$2:$C$3272,$B31,'Progress Tracker'!$G$2:$G$3272),1)
B32: Unit III - Kinetic Theory of Gases | C32: =COUNTIF('Progress Tracker'!$C$2:$C$3272,$B32) | D32: =COUNTIFS('Progress Tracker'!$C$2:$C$3272,$B32,'Progress Tracker'!$I$2:$I$3272,"Done") | E32: =IFERROR(D32/C32,0) | F32: =ROUND(SUMIF('Progress Tracker'!$C$2:$C$3272,$B32,'Progress Tracker'!$G$2:$G$3272),1)
B33: Unit IV - Classical Statistical Mechanics | C33: =COUNTIF('Progress Tracker'!$C$2:$C$3272,$B33) | D33: =COUNTIFS('Progress Tracker'!$C$2:$C$3272,$B33,'Progress Tracker'!$I$2:$I$3272,"Done") | E33: =IFERROR(D33/C33,0) | F33: =ROUND(SUMIF('Progress Tracker'!$C$2:$C$3272,$B33,'Progress Tracker'!$G$2:$G$3272),1)
B34: Unit V - Interacting Particles | C34: =COUNTIF('Progress Tracker'!$C$2:$C$3272,$B34) | D34: =COUNTIFS('Progress Tracker'!$C$2:$C$3272,$B34,'Progress Tracker'!$I$2:$I$3272,"Done") | E34: =IFERROR(D34/C34,0) | F34: =ROUND(SUMIF('Progress Tracker'!$C$2:$C$3272,$B34,'Progress Tracker'!$G$2:$G$3272),1)
B35: Units VI–VII - Quantum Statistical Mechanics and Ideal Quantum Gases | C35: =COUNTIF('Progress Tracker'!$C$2:$C$3272,$B35) | D35: =COUNTIFS('Progress Tracker'!$C$2:$C$3272,$B35,'Progress Tracker'!$I$2:$I$3272,"Done") | E35: =IFERROR(D35/C35,0) | F35: =ROUND(SUMIF('Progress Tracker'!$C$2:$C$3272,$B35,'Progress Tracker'!$G$2:$G$3272),1)
B36: B.2.2 V. Balakrishnan - Physical Applications of Stochastic Processes | C36: =COUNTIF('Progress Tracker'!$C$2:$C$3272,$B36) | D36: =COUNTIFS('Progress Tracker'!$C$2:$C$3272,$B36,'Progress Tracker'!$I$2:$I$3272,"Done") | E36: =IFERROR(D36/C36,0) | F36: =ROUND(SUMIF('Progress Tracker'!$C$2:$C$3272,$B36,'Progress Tracker'!$G$2:$G$3272),1)
B37: B.2.3 V. Balakrishnan - Nonequilibrium Statistical Mechanics | C37: =COUNTIF('Progress Tracker'!$C$2:$C$3272,$B37) | D37: =COUNTIFS('Progress Tracker'!$C$2:$C$3272,$B37,'Progress Tracker'!$I$2:$I$3272,"Done") | E37: =IFERROR(D37/C37,0) | F37: =ROUND(SUMIF('Progress Tracker'!$C$2:$C$3272,$B37,'Progress Tracker'!$G$2:$G$3272),1)
B38: B.2.5 Statistical honesty: the Zuckerman thread | C38: =COUNTIF('Progress Tracker'!$C$2:$C$3272,$B38) | D38: =COUNTIFS('Progress Tracker'!$C$2:$C$3272,$B38,'Progress Tracker'!$I$2:$I$3272,"Done") | E38: =IFERROR(D38/C38,0) | F38: =ROUND(SUMIF('Progress Tracker'!$C$2:$C$3272,$B38,'Progress Tracker'!$G$2:$G$3272),1)
... B347: B.10 PyEMMA and Markov state models - 29 videos | C347: =COUNTIF('Progress Tracker'!$C$2:$C$3272,$B347) | D347: =COUNTIFS('Progress Tracker'!$C$2:$C$3272,$B347,'Progress Tracker'!$I$2:$I$3272,"Done") | E347: =IFERROR(D347/C347,0) | F347: =ROUND(SUMIF('Progress Tracker'!$C$2:$C$3272,$B347,'Progress Tracker'!$G$2:$G$3272),1)

Sheet Core Path
A1: The core path
A2: The flagged essentials from the foundations, the classical and learned prediction families, design, benchmarking and performance. If you do nothing else, do these.
A4: # | B4: Section | C4: Title | D4: Speaker / host | E4: Duration | F4: Status | G4: Watch
A5: 1 | B5: B.2.2 V. Balakrishnan - Physical Applications of Stochastic Processes | C5: Langevin dynamics (Part 1 | E5: 57:53 | F5: Not started | G5: ▶ watch
A6: 2 | B6: B.2.2 V. Balakrishnan - Physical Applications of Stochastic Processes | C6: Langevin dynamics (Part 2 | E6: 51:46 | F6: Not started | G6: ▶ watch
A7: 3 | B7: B.2.2 V. Balakrishnan - Physical Applications of Stochastic Processes | C7: Langevin dynamics (Part 3 | E7: 58:39 | F7: Not started | G7: ▶ watch
A8: 4 | B8: B.2.2 V. Balakrishnan - Physical Applications of Stochastic Processes | C8: Langevin dynamics (Part 4 | E8: 57:15 | F8: Not started | G8: ▶ watch
A9: 5 | B9: B.2.2 V. Balakrishnan - Physical Applications of Stochastic Processes | C9: Itô and Fokker-Planck equations for diffusion processes | E9: 47:42 | F9: Not started | G9: ▶ watch
A10: 6 | B10: B.2.2 V. Balakrishnan - Physical Applications of Stochastic Processes | C10: First passage time (Part 1 | E10: 59:50 | F10: Not started | G10: ▶ watch
A11: 7 | B11: B.2.2 V. Balakrishnan - Physical Applications of Stochastic Processes | C11: First passage time (Part 2 | E11: 1:03:14 | F11: Not started | G11: ▶ watch
A12: 8 | B12: B.2.3 V. Balakrishnan - Nonequilibrium Statistical Mechanics | C12: Linear response theory (Part 1 | E12: 47:55 | F12: Not started | G12: ▶ watch
A13: 9 | B13: B.2.3 V. Balakrishnan - Nonequilibrium Statistical Mechanics | C13: Fokker-Planck equations (Part 1 | E13: 50:22 | F13: Not started | G13: ▶ watch
A14: 10 | B14: B.2.3 V. Balakrishnan - Nonequilibrium Statistical Mechanics | C14: The generalized Langevin equation (Part 1 | E14: 1:00:14 | F14: Not started | G14: ▶ watch
A15: 11 | B15: B.2.3 V. Balakrishnan - Nonequilibrium Statistical Mechanics | C15: The Wiener process (standard Brownian motion | E15: 1:03:10 | F15: Not started | G15: ▶ watch
A16: 12 | B16: B.2.5 Statistical honesty: the Zuckerman thread | C16: Introduction to Weighted Ensemble Simulation | D16: video, 31 min | E16: 31:14 | F16: Not started | G16: ▶ watch
A17: 13 | B17: B.2.5 Statistical honesty: the Zuckerman thread | C17: Recent Advances in Weighted Ensemble Simulation | D17: video, 36 min | E17: 35:59 | F17: Not started | G17: ▶ watch
A18: 14 | B18: B.2.5 Statistical honesty: the Zuckerman thread | C18: Simple trajectory physics for path sampling and improving Markov models | D18: video, 33 min | E18: 30:27 | F18: Not started | G18: ▶ watch
A19: 15 | B19: B.3.8 Large-scale data, search, and complexity | C19: Quincey Koziol (HDF Group / LBNL | D19: Introduction to HDF5 | E19: 1:17:10 | F19: Not started | G19: ▶ watch
A20: 16 | B20: B.3.8 Large-scale data, search, and complexity | C20: Quincey Koziol | D20: Parallel HDF5 | E20: 40:01 | F20: Not started | G20: ▶ watch
A21: 17 | B21: B.3.8 Large-scale data, search, and complexity | C21: Quincey Koziol | D21: Scalable HDF5 | E21: 1:13:42 | F21: Not started | G21: ▶ watch
A22: 18 | B22: B.3.8 Large-scale data, search, and complexity | C22: Billion-scale Approximate Nearest Neighbor Search | D22: Yusuke Matsui (CVPR 2020 tutorial | E22: 47:36 | F22: Not started | G22: ▶ watch
A23: 19 | B23: B.4.3 Protein structure and folding | C23: IPD lecture 1: Intro + review of protein structure (41:06 | E23: 41:06 | F23: Not started | G23: ▶ watch
A24: 20 | B24: B.4.3 Protein structure and folding | C24: IPD lecture 2: Protein Geometry (1:09:31 | E24: 1:09:31 | F24: Not started | G24: ▶ watch
A25: 21 | B25: B.1 Foundations - the integrator, the thermostat, the box | C25: Rosetta: Refining structures with minimization and Monte Carlo | D25: RosettaCommons | E25: 39:13 | F25: Not started | G25: ▶ watch
A26: 22 | B26: B.2 Anton and the long-timescale program | C26: Large-scale conformational transition in a membrane transporter | D26: Trebesch / Fakharzadeh, Tajkhorshid lab (Broad MIA | E26: 1:34:25 | F26: Not started | G26: ▶ watch
A27: 23 | B27: B.3 Force fields in practice - and the parts that are wrong | C27: Benchmark and Critical Evaluation for ML Force Fields | D27: Xiang Fu (Valence | E27: 1:00:38 | F27: Not started | G27: ▶ watch
A28: 24 | B28: B.3 Force fields in practice - and the parts that are wrong | C28: Improving Speed and Accuracy of NN Interatomic Potentials | D28: Valence | E28: 54:24 | F28: Not started | G28: ▶ watch
A29: 25 | B29: B.3 Force fields in practice - and the parts that are wrong | C29: Allegro: Local Equivariant Representations for Large-Scale Dynamics | D29: Musaelian (Harvard, Valence | E29: 1:09:17 | F29: Not started | G29: ▶ watch
A30: 26 | B30: B.3 Force fields in practice - and the parts that are wrong | C30: Learning QM Using Embedding, Symmetric Polynomials and Composition | D30: Gábor Csányi (Valence | E30: 38:34 | F30: Not started | G30: ▶ watch
A31: 27 | B31: B.3 Force fields in practice - and the parts that are wrong | C31: Learning ML Interatomic Potentials | D31: De Fabritiis (ML4DD | E31: 51:39 | F31: Not started | G31: ▶ watch
A32: 28 | B32: B.3 Force fields in practice - and the parts that are wrong | C32: Orb-v3: atomistic simulation at scale | D32: Duignan & Vandenhaute (Valence | E32: 1:13:35 | F32: Not started | G32: ▶ watch
A33: 29 | B33: B.3 Force fields in practice - and the parts that are wrong | C33: Transformers Discover Molecular Structure Without Graph Priors | D33: Kreiman (Berkeley, Valence | E33: 1:04:09 | F33: Not started | G33: ▶ watch
A34: 30 | B34: B.3 Force fields in practice - and the parts that are wrong | C34: Stability-Aware Boltzmann Estimator (StABlE) Training | D34: Sanjeev Raja (Valence | E34: 1:22:10 | F34: Not started | G34: ▶ watch
A35: 31 | B35: B.3 Force fields in practice - and the parts that are wrong | C35: AquaGen: generative models at MD precision on thousands of atoms | D35: Valence | E35: 1:16:27 | F35: Not started | G35: ▶ watch
A36: 32 | B36: B.4 Running MD correctly - the practitioner layer | C36: BioExcel Building Blocks: interoperable simulation workflows | D36: RosettaCommons Workflows | E36: 36:36 | F36: Not started | G36: ▶ watch
... A49: 45 | B49: E.4.1 Architecture fundamentals | C49: GPU optimization workshop (OpenAI, NVIDIA, PyTorch | D49: Saroufim, Chetlur, Tillet | E49: 2:33:53 | F49: Not started | G49: ▶ watch
A50: 46 | B50: E.4.2 Programming Massively Parallel Processors - the complete course | C50: GPU Architecture | E50: 1:23:57 | F50: Not started | G50: ▶ watch
A51: 47 | B51: E.4.2 Programming Massively Parallel Processors - the complete course | C51: Memory and Tiling | E51: 1:24:26 | F51: Not started | G51: ▶ watch
A52: 48 | B52: E.4.2 Programming Massively Parallel Processors - the complete course | C52: Performance Considerations | E52: 1:08:05 | F52: Not started | G52: ▶ watch
A53: 49 | B53: E.4.2 Programming Massively Parallel Processors - the complete course | C53: Profiling | E53: 1:00:59 | F53: Not started | G53: ▶ watch
...

Sheet Paired Reading
A1: Watch this, then read that
A2: The core study device. Watch the talk, read the paper it narrates, and write the gap between them. The question in the last column is what to hold while you do it.
A4: # | B4: Part | C4: Section | D4: Watch this | E4: Then read this | F4: Hold this question | G4: Done
A5: 1 | B5: Part I - Foundations | C5: B.1.5 Paired reading - Module B.1 | D5: Strang 18.065 Lec 7 (Eckart-Young | E5: Any efficient-attention or memory-reduction paper for structure models | F5: Which block in a structure predictor is low-rank, and has anyone exploited it?
A6: 2 | B6: Part I - Foundations | C6: B.1.5 Paired reading - Module B.1 | D6: Strang 18.065 Lec 34 (Procrustes | E6: Kabsch 1976 | F6: Your RMSD calculation is solving a Procrustes problem. What does the SVD step do?
A7: 3 | B7: Part I - Foundations | C7: B.1.5 Paired reading - Module B.1 | D7: Johnson & Edelman 6.1 (adjoint ODE | E7: Chen et al. 2018, Neural Ordinary Differential Equations | F7: What is the memory cost of the adjoint method, and when is checkpointing better?
A8: 4 | B8: Part I - Foundations | C8: B.1.5 Paired reading - Module B.1 | D8: Johnson & Edelman 8.1 (eigenproblems | E8: Any normal-mode analysis paper | F8: Could you optimize a protein's normal-mode spectrum by gradient descent?
A9: 5 | B9: Part I - Foundations | C9: B.1.5 Paired reading - Module B.1 | D9: Gallager 6.262 (Markov chains | E9: Prinz et al. 2011 | F9: What must hold for a coarse-grained chain to remain Markovian?
A10: 6 | B10: Part I - Foundations | C10: B.1.5 Paired reading - Module B.1 | D10: Rigollet 18.650 | E10: Any design paper reporting a success rate | F10: What is the confidence interval on 3/50? Is it ever reported?
A11: 7 | B11: Part I - Foundations | C11: B.1.5 Paired reading - Module B.1 | D11: McElreath, Statistical Rethinking | E11: Kapoor & Narayanan 2023 | F11: Draw the causal diagram for a design benchmark. Where does leakage enter?
A12: 8 | B12: Part I - Foundations | C12: B.1.5 Paired reading - Module B.1 | D12: MacKay Lec 1–5 | E12: Shannon 1948 | F12: Perplexity measures compression. What would show the compression is biophysical?
A13: 9 | B13: Part I - Foundations | C13: B.1.5 Paired reading - Module B.1 | D13: MacKay Lec 12–13 | E13: Metropolis et al. 1953; Neal on slice sampling | F13: Detailed balance is sufficient, not necessary. What is necessary?
A14: 10 | B14: Part I - Foundations | C14: B.1.5 Paired reading - Module B.1 | D14: Hennig, Probabilistic ML | E14: Guo et al., On calibration of modern neural networks | F14: Is pLDDT calibrated? Design the experiment that settles it.
A15: 11 | B15: Part I - Foundations | C15: B.2.7 Paired reading - Module B.2 | D15: Kardar Units I–II | E15: Any text on ensemble equivalence | F15: When do canonical and microcanonical disagree, and does it ever matter for a protein?
A16: 12 | B16: Part I - Foundations | C16: B.2.7 Paired reading - Module B.2 | D16: Kardar Unit IV | E16: Zwanzig 1954 | F16: FEP is exact. Why does it fail in practice, and what quantity governs the failure?
... A38: 34 | B38: Part I - Foundations | C38: B.3.11 Paired reading - Module B.3 | D38: Kolter & Chen 10-414 Lec 4–5 | E38: Baydin et al. 2018, Automatic differentiation in machine learning: a survey | F38: Implement reverse-mode AD. Then differentiate through an ODE solver.
A39: 35 | B39: Part I - Foundations | C39: B.3.11 Paired reading - Module B.3 | D39: Kolter & Chen 10-414 Lec 11–13 | F39: Add a GPU backend. Then add one equivariant op that does not exist in PyTorch.
A40: 36 | B40: Part I - Foundations | C40: B.3.11 Paired reading - Module B.3 | D40: CS336 Lec 6, Kernels, Triton, XLA | E40: Dao et al. 2022, FlashAttention | F40: IO-awareness beat FLOP-reduction. What is the molecular analogue?
A41: 37 | B41: Part I - Foundations | C41: B.3.11 Paired reading - Module B.3 | D41: Xing 10-708, belief propagation | E41: Any TRBP or dual-decomposition packing paper; then Dauparas et al. 2022 | F41: Write ProteinMPNN's factor graph. What inference is it doing?
A42: 38 | B42: Part I - Foundations | C42: B.3.11 Paired reading - Module B.3 | D42: Xing 10-708, variational inference | E42: Morcos et al. 2011 (DCA | F42: DCA is inference in a Potts model. What does mean-field cost you?
A43: 39 | B43: Part I - Foundations | C43: B.3.11 Paired reading - Module B.3 | D43: Matsui, Billion-scale ANN | E43: van Kempen et al. 2024 (Foldseek | F43: Foldseek turns structure search into sequence search. What is the 3Di alphabet, formally?
A44: 40 | B44: Part I - Foundations | C44: B.3.11 Paired reading - Module B.3 | D44: Demaine 6.890 | E44: Desmet et al. 1992 (DEE); Pierce & Winfree 2002 | F44: Construct the reduction showing packing is NP-hard. Then find a tractable restriction.
A45: 41 | B45: Part I - Foundations | C45: B.3.11 Paired reading - Module B.3 | D45: Pavlo 15-721, columnar storage | E45: Any Parquet/Arrow specification | F45: Your trajectory format is row-major. What would columnar buy you?
A46: 42 | B46: Part I - Foundations | C46: B.3.11 Paired reading - Module B.3 | D46: Koziol, HDF5 | F46: Chunking and compression determine slice latency. Benchmark your own trajectory I/O.
A47: 43 | B47: Part I - Foundations | C47: B.3.11 Paired reading - Module B.3 | D47: CodeRefinery, testing | E47: Wilson et al. 2014, Best Practices for Scientific Computing | F47: Write one test that would catch a silent numerical regression in your pipeline.
A48: 44 | B48: Part I - Foundations | C48: B.4.7 Paired reading - B.4 | D48: Lindahl, Biophysical Chemistry | E48: Dill & Bromberg, Molecular Driving Forces, ch. 1–10 | F48: Work the problems. This is the one textbook to do properly.
A49: 45 | B49: Part I - Foundations | C49: B.4.7 Paired reading - B.4 | D49: Phillips, Physical Biology of the Cell | E49: The book's estimation chapters | F49: Estimate three quantities in your own project before computing them.
A50: 46 | B50: Part I - Foundations | C50: B.4.7 Paired reading - B.4 | D50: IPD lectures 1–2 | E50: Richardson 1981, Adv Protein Chem 34:167 | F50: Learn twenty folds by sight. It pays off constantly.
A51: 47 | B51: Part I - Foundations | C51: B.4.7 Paired reading - B.4 | D51: Atlas R.5 enzyme talks | E51: Warshel et al. 2006, Chem Rev 106:3210 | F51: Preorganization versus dynamics. Take a side and defend it.
A52: 48 | B52: Part II - The Method Atlas | C52: A.6 Paired reading - Atlas A | D52: Tajkhorshid, Classical Force Fields | E52: Best et al. 2012 (CHARMM36); Maier et al. 2015 (ff14SB | F52: For each term, name the experimental or QM data it was fit to.
A53: 49 | B53: Part II - The Method Atlas | C53: A.6 Paired reading - Atlas A | D53: OpenFF workshops | E53: Any OpenFF parameterization paper | F53: How is a torsion parameter determined, and how transferable is it?
A54: 50 | B54: Part II - The Method Atlas | C54: A.6 Paired reading - Atlas A | D54: Ponder, AMOEBA accuracy | E54: Ponder et al. 2010, JPCB 114:2549 | F54: What does polarizability buy, and is it worth the cost?
A55: 51 | B55: Part II - The Method Atlas | C55: A.6 Paired reading - Atlas A | D55: Cramer, Continuum solvent electrostatics | E55: Honig & Nicholls 1995, Science 268:1144 | F55: When is a continuum dielectric legitimate, and what is the dielectric constant of a protein?
A56: 52 | B56: Part II - The Method Atlas | C56: A.6 Paired reading - Atlas A | D56: Cooper / Wilson, CECAM electrostatics | E56: Baker et al. 2001, PNAS 98:10037 (APBS | F56: How is PB actually solved at protein scale, and what is the discretization error?
A57: 53 | B57: Part II - The Method Atlas | C57: A.6 Paired reading - Atlas A | D57: Onufriev, Generalized Born | E57: Still et al. 1990, JACS 112:6127; Onufriev et al. 2004, Proteins 55:383 | F57: GB approximates PB. Derive the approximation and state when it fails.
A58: 54 | B58: Part II - The Method Atlas | C58: A.6 Paired reading - Atlas A | D58: Barroso / BioExcel, Constant-pH MD | E58: Swails, York & Roitberg 2014, JCTC 10:1341 | F58: A fixed protonation state is an assumption. How large is the error?
... A308: 304 | B308: Part II - The Method Atlas | C308: P.11 Paired reading - Atlas P | D308: Rettie, cyclic peptides with AF | E308: Rettie et al. 2023, Nat Commun 15 | F308: AF2 never saw cyclic backbones. Why does the offset trick work at all?
A309: 305 | B309: Part II - The Method Atlas | C309: P.11 Paired reading - Atlas P | D309: Ovchinnikov, AlphaFold 4 | F309: Extract every open problem named, with the date.
A310: 306 | B310: Part II - The Method Atlas | C310: Q.8 Paired reading - Atlas Q | D310: Rives, Evolutionary Scale LMs | E310: Rives et al. 2021, PNAS 118:e2016239118 | F310: What does "unsupervised" mean when the data is a curated database?
A311: 307 | B311: Part II - The Method Atlas | C311: Q.8 Paired reading - Atlas Q | D311: Rao, ESM3 | E311: Lin et al. 2023, Science 379:1123; Hayes et al. 2025, Science 387:850 | F311: ESMFold is fast and less accurate than AF2. Where exactly is the trade?
...

Sheet Checkpoints
A1: Derivation checkpoints
A2: Things to derive from a blank page. Three states, and only the third counts: not started, attempted, can reproduce from blank paper.
A4: # | B4: Family | C4: What to derive | D4: State | E4: Date
A5: 1 | B5: From potential energy functions (Family A | C5: 1. Write down every term in a modern molecular mechanics force field and name | D5: Not started
A6: 2 | B6: From potential energy functions (Family A | C6: 2. Derive the Lennard-Jones potential's relationship to dispersion and Pauli | D6: Not started
A7: 3 | B7: From potential energy functions (Family A | C7: 3. Explain Ewald summation and why particle-mesh Ewald is O(N log N). State what | D7: Not started
A8: 4 | B8: From potential energy functions (Family A | C8: 4. Explain what a polarizable force field adds, and why the added cost has not | D8: Not started
A9: 5 | B9: From potential energy functions (Family A | C9: 5. Derive the functional form of a machine-learned interatomic potential's | D9: Not started
A10: 6 | B10: From molecular dynamics (Family B | C10: 6. Show that velocity Verlet is symplectic and time-reversible, and explain what | D10: Not started
A11: 7 | B11: From molecular dynamics (Family B | C11: 7. Derive the Langevin equation's fluctuation-dissipation relation and explain | D11: Not started
A12: 8 | B12: From molecular dynamics (Family B | C12: 8. Explain why constraining bonds to hydrogen permits a larger timestep, and | D12: Not started
A13: 9 | B13: From molecular dynamics (Family B | C13: 9. Show why the Berendsen thermostat does not sample the canonical ensemble, and | D13: Not started
A14: 10 | B14: From molecular dynamics (Family B | C14: 10. Derive the pressure estimator from the virial, and explain why it is noisy. | D14: Not started
A15: 11 | B15: From Monte Carlo (Family C | C15: 11. State the Metropolis-Hastings acceptance criterion and prove it satisfies detailed balance for an arbitrary symmetric or asymmetric proposal. | D15: Not started
A16: 12 | B16: From Monte Carlo (Family C | C16: 12. Explain why detailed balance is sufficient but not necessary for correct sampling, and give one method that is correct without it. | D16: Not started
... A77: 73 | B77: From RNA (Family T | C77: 73. Quantify the RNA-versus-protein data gap from the PDB directly, then decompose the performance gap into the six causes in Atlas T.10 and argue, with evidence, which are contingent and which are structural. | D77: Not started

Sheet Capstones
A1: Capstone projects
A2: Begin each as soon as its prerequisite families are done. Do not wait until the end.
A4: # | B4: Project | C4: Start after | D4: What it is | E4: Status
A5: I | B5: The reimplementation | C5: after Families B, C, I | D5: Build a Markov state model pipeline from scratch. Featurization, TICA, clustering, transition matrix estimation with reversibility, implied timescales, Chapman-Kolmogorov. Validate against PyEMMA on data you already have. Why: it forces you to confront, in code, every place the statistics can silently fail. After this you will never trust an MSM figure without asking about the lag time. | E5: Not started
A6: II | B6: The equivariance crossover | C6: after Family O | D6: Find the dataset size at which an architectural symmetry constraint stops paying for itself. Train equivariant and non-equivariant versions of one architecture on one task across a data-size sweep, and plot the crossover. Why: AlphaFold3 dropped AF2's explicitly equivariant structure module and got better, while low-data molecular problems clearly still benefit. Nobody has published that curve for protein structure, and it would be cited constantly. See Atlas O.3 and O.4. | E6: Not started
A7: III | B7: The over-optimization curve | C7: after Families P, R, S | D7: Measure where your design filters stop tracking reality. Take a target with experimental data at several optimization strengths and plot wet-lab success against filter stringency. The curve has a maximum. Find it. Why: Gao, Schulman & Hilton did exactly this for learned reward models in language and found true performance peaks and then falls while the proxy keeps climbing. Design pipelines optimize against pLDDT and interface pAE with no equivalent measurement. See D.6.1 and Atlas R.10. | E7: Not started
A8: IV | B8: The Boltzmann-generator audit | C8: after Family D | D8: Test whether a learned sampler actually samples the target distribution. Take a system where you can afford converged reference sampling, generate from a flow or diffusion emulator, compute importance weights, and report the effective sample size and the free energy difference against the reference. Why: the claim these methods make is Boltzmann sampling, not plausible structures, and the distinction is checkable. See Atlas D.6. | E8: Not started
A9: V | B9: The learned prior meets sparse data | C9: after Family K | D9: Work out the correct way to combine a learned structural prior with averaged experimental restraints without double-counting. Hummer and Köfinger solved this for simulation ensembles; nobody has solved it for AlphaFold-class priors, which is what every crosslink-guided and density-guided prediction now does informally. Why: it is a well-posed inference question with immediate practical payoff, and it sits directly on top of any restraint-guided prediction work. See Atlas K.3. | E9: Not started
A10: VI | B10: The whole-cell parameter gap | C10: after Family G | D10: Take the minimal-cell whole-cell model and ask what it would take to put a designed protein into it. Enumerate every parameter the model needs, mark which are computable today, and quantify how wrong the computable ones are. Why: it is the clearest statement of the distance between design and cell biology, and nobody in design has written it down. See Atlas G.2. | E10: Not started
A11: VII | B11: The standing assessment | C11: ambitious | D11: Build the blind assessment for de novo design that does not exist. Target set, held out by a third party, experimental readout, published protocol, annual cadence. Adaptyv is the proof it can work; it is not yet CASP. Why: this is the single largest piece of missing infrastructure in the field. It is hard because it needs wet-lab partners, which is exactly why nobody has done it. See Atlas R.4 and S.1. | E11: Not started
A12: VIII | B12: Interpretability with ground truth | C12: after Family Q and D.9 | D12: Train sparse autoencoders on an MSA Transformer and evaluate the recovered features against Pfam domains, CATH folds, catalytic-site annotations and transmembrane spans. Report precision and recall of features against real labels - which language interpretability literally cannot do. Why: an MSA Transformer attending across an alignment to find the corresponding residue in a homolog is an induction head doing structural biology, and nobody has looked. This is the most tractable bridge project in this document, and it benefits the AI field more than the biology field. See Atlas Q.4, D.7.5, D.9 and D.10.1. | E12: Not started
A13: IX | B13: The RNA gap | C13: after Family Q | D13: Characterize, quantitatively, why RNA structure prediction is behind protein structure prediction. Is it data volume, conformational heterogeneity, the ion atmosphere, or the absence of a CASP-grade assessment? Decompose it. Why: this is the Rhiju Das question, it is stated honestly nowhere, and the answer determines where effort should go. See Atlas Q.5. | E13: Not started
A14: X | B14: Scaling laws for structure prediction | C14: after D.5 | D14: Fit the functional form of structure-prediction performance in data, parameters and compute. Subsample the PDB at many fractions, train a fixed architecture at several sizes, fit the surface, and use Kudugunta's methodology critique as the checklist. Why: it is the quantitative answer to "should we fund more structure determination or more compute," and that question is currently decided by opinion. See D.5.4. | E14: Not started
A15: XI | B15: The speedup | C15: after Part IV | D15: Make one real tool measurably faster and get the change merged. Not a fork, not a benchmark script - an upstream contribution to something people run: GROMACS, OpenMM, OpenFold, Boltz, ColabFold, e3nn, MDAnalysis. Profile it, find the actual bottleneck, fix it, show the number, defend it in review. Why: it is the single most verifiable contribution in this entire document - a speedup either reproduces on someone else's machine or it does not - and it is how you become known to the people who maintain the tools you depend on. It is also the one capstone where the field's gatekeeping is purely technical. See Part IV, especially E.8. | E15: Not started

Sheet Papers
A1: Paired papers
A2: Every citation in the curriculum, with the section that discusses it.
A4: # | B4: Part | C4: Section | D4: Citation | E4: Read
A5: 1 | B5: Part I - Foundations | C5: B.4.2 The forces, one at a time | D5: Chandler 2005, Nature 437:640 (interfaces and the driving force of hydrophobic assembly)
A6: 2 | B6: Part I - Foundations | C6: B.4.2 The forces, one at a time | D6: Baldwin 2007, J Mol Biol 371:283
A7: 3 | B7: Part I - Foundations | C7: B.4.2 The forces, one at a time | D7: Pace et al. 2014, J Biol Chem 289:19165 (contribution of hydrogen bonding to stability)
A8: 4 | B8: Part I - Foundations | C8: B.4.2 The forces, one at a time | D8: Fleming & Rose 2005, Protein Sci 14:1911
A9: 5 | B9: Part I - Foundations | C9: B.4.2 The forces, one at a time | D9: Dill 1990, Biochemistry 29:7133 (dominant forces in protein folding - the review to read first)
A10: 6 | B10: Part I - Foundations | C10: B.4.3 Protein structure and folding | D10: Ramachandran et al. 1963, J Mol Biol 7:95
A11: 7 | B11: Part I - Foundations | C11: B.4.3 Protein structure and folding | D11: Anfinsen 1973, Science 181:223
A12: 8 | B12: Part I - Foundations | C12: B.4.3 Protein structure and folding | D12: Richardson 1981, Adv Protein Chem 34:167 (the anatomy and taxonomy of protein structure - still the best single document on folds)
A13: 9 | B13: Part I - Foundations | C13: B.4.3 Protein structure and folding | D13: Levinthal 1969
A14: 10 | B14: Part I - Foundations | C14: B.4.3 Protein structure and folding | D14: Bryngelson & Wolynes 1987, PNAS 84:7524 (the funnel)
A15: 11 | B15: Part I - Foundations | C15: B.4.4 Enzymology and catalysis | D15: Pauling 1946, Chem Eng News 24:1375 (transition state stabilization - two pages)
A16: 12 | B16: Part I - Foundations | C16: B.4.4 Enzymology and catalysis | D16: Warshel et al. 2006, Chem Rev 106:3210 (electrostatic basis for enzyme catalysis)
... A551: 547 | B551: Part V (continued) - Research Craft | C551: C.10 Reproducibility and not fooling yourself | D551: Open Science Collaboration 2015, Science 349:aac4716

Sheet Sections
A1: Table of contents
A2: Every section, in document order, with what it holds.
A4: # | B4: Part | C4: Section | D4: Videos | E4: Hours
A5: 1 | B5: Part I - Foundations | C5: MIT 18.065 - Matrix Methods in Data Analysis, Signal Processing and Machine Learning | D5: 36 | E5: 28.2
A6: 2 | B6: Part I - Foundations | C6: MIT 18.S096 - Matrix Calculus for Machine Learning and Beyond | D6: 17 | E6: 13.9
A7: 3 | B7: Part I - Foundations | C7: David MacKay - Information Theory, Pattern Recognition and Neural Networks | D7: 16 | E7: 17.6
A8: 4 | B8: Part I - Foundations | C8: Unit I - Thermodynamics | D8: 4 | E8: 5.5
A9: 5 | B9: Part I - Foundations | C9: Unit II - Probability | D9: 2 | E9: 2.8
A10: 6 | B10: Part I - Foundations | C10: Unit III - Kinetic Theory of Gases | D10: 5 | E10: 6.8
A11: 7 | B11: Part I - Foundations | C11: Unit IV - Classical Statistical Mechanics | D11: 3 | E11: 4.2
A12: 8 | B12: Part I - Foundations | C12: Unit V - Interacting Particles | D12: 5 | E12: 6.9
A13: 9 | B13: Part I - Foundations | C13: Units VI–VII - Quantum Statistical Mechanics and Ideal Quantum Gases | D13: 7 | E13: 9.7
A14: 10 | B14: Part I - Foundations | C14: B.2.2 V. Balakrishnan - Physical Applications of Stochastic Processes | D14: 29 | E14: 28.3
A15: 11 | B15: Part I - Foundations | C15: B.2.3 V. Balakrishnan - Nonequilibrium Statistical Mechanics | D15: 36 | E15: 32.8
A16: 12 | B16: Part I - Foundations | C16: B.2.5 Statistical honesty: the Zuckerman thread | D16: 3 | E16: 1.6
... A325: 321 | B325: Part VI - Appendices | C325: B.10 PyEMMA and Markov state models - 29 videos | D325: 22 | E325: 9.1
